Workbook

Sheet DATA ENTRY
D2: CLASS RECORD - COURSE DETAILS
G3: LECTURE GRADING SYSTEM
D4: LECTURE | H4: CLASS STANDING | I4: EXAMS | J4: CHARACTER | K4: TOTAL
D5: SYSTEM | E5: World Citi Colleges
D6: CAMPUS | E6: Antipolo City | G6: PRELIM | H6: 0.1333 | I6: 0.1667 | J6: 0.0333 | K6: =SUM(H6:J6) -> 0.3333 | L6: =(K6/100)*100 -> 0.3333
A7: COURSE INFORMATION | G7: MIDTERM | H7: 0.1333 | I7: 0.1667 | J7: 0.0333 | K7: =SUM(H7:J7) -> 0.3333 | L7: =(K7/100)*100 -> 0.3333
G8: FINAL | H8: 0.1333 | I8: 0.1667 | J8: 0.0333 | K8: =SUM(H8:J8) -> 0.3333 | L8: =(K8/100)*100 -> 0.3333
B9: SCHOOL YEAR | D9: INSTRUCTOR | G9: TOTAL | K9: =SUM(K6:K8) -> 0.9999
B10: SEMESTER | D10: DEAN
B11: DEPARTMENT | D11: AVP FOR ACADEMIC AFFAIRS
B12: COURSE CODE | D12: ACADEMIC PROGRAM
B13: COURSE DESCRIPTION | D13: YEAR LEVEL & SECTION
D14: SUBJECT TYPE:
B16: SCHEDULE
C17: LECTURE | E17: STUDENT FINAL MARKING
B18: DAY | D18: DRP | E18: Failure Due to Absenses
B19: TIME | D19: INC | E19: Incomplete
B20: ROOM | D20: IP | E20: In Progress
B21: UNIT
A23: STUDENT LIST
A25: NO. | B25: STUDENT NUMBER | C25: STUDENT NAME | D25: ACADEMIC PROGRAM
A26: =ROW(A1) -> 1 | B26: 24-QC13447 | C26: ACOB, TRIXIE JUNIO
A27: =ROW(A2) -> 2 | B27: 24-QC12756 | C27: ACOSTA, DANNMICHAEL DULLA
A28: =ROW(A3) -> 3 | B28: 24-QC12714 | C28: AGUILAR, KIMBERLY ASHLEY CALUMPIT
A29: =ROW(A4) -> 4 | B29: 24-QC13807 | C29: ARANDIA, JOHN PAUL TAGULAO
A30: =ROW(A5) -> 5 | B30: 24-QC13547 | C30: AROCHA, NESHANEL
A31: =ROW(A6) -> 6 | B31: 24-QC13905 | C31: ARRIOLA, GABRIEL PEHID
A32: =ROW(A7) -> 7 | B32: 23-QC03433 | C32: AVILES, ANTONIO TITOY
A33: =ROW(A8) -> 8 | B33: 24-QC12867 | C33: BASILIO, CHARLES PLURAL
A34: =ROW(A9) -> 9 | B34: 24-QC14612 | C34: BRINGINO, RALPH REGOR
A35: =ROW(A10) -> 10 | B35: 24-QC13948 | C35: CABRERA, CHARLES IAN
A36: =ROW(A11) -> 11 | B36: 24-QC13477 | C36: CAMPOS, RYAN MIGUEL PACAYRA
A37: =ROW(A12) -> 12 | B37: 24-QC14613 | C37: CASTILLO, LOUIS ANGELO CRAME
... A68: =ROW(A43) -> 43 | B68: 24-QC13435 | C68: YABUT, CARYSE AMARA UNTALAN
A69: =ROW(A44) -> 44
A70: =ROW(A45) -> 45
A71: =ROW(A46) -> 46
A72: =ROW(A47) -> 47
A73: =ROW(A48) -> 48
A74: =ROW(A49) -> 49
...

Sheet PRELIM
A1: WORLD CITI COLLEGES
A2: ='DATA ENTRY'!E6 -> Antipolo City
A3: CLASS RECORD
A4: PRELIMINARY PERIOD
B5: Intsructor: | C5: ='DATA ENTRY'!$E$9 -> 0 | J5: Day: | K5: ='DATA ENTRY'!$C$18 -> 0 | P5: Unit: | Q5: ='DATA ENTRY'!C21 -> 0
B6: ='DATA ENTRY'!D10 -> DEAN | C6: ='DATA ENTRY'!$E$10 -> 0 | J6: Time: | K6: ='DATA ENTRY'!$C$19 -> 0 | P6: Year & Sec: | Q6: ='DATA ENTRY'!E13 -> 0
B7: Department: | C7: ='DATA ENTRY'!$C$11 -> 0 | J7: Room: | K7: ='DATA ENTRY'!C20 -> 0
B8: Course Code: | C8: ='DATA ENTRY'!$C$12 -> 0 | J8: Semester: | K8: ='DATA ENTRY'!C10 -> 0
B9: Course Description: | C9: ='DATA ENTRY'!$C$13 -> 0
B10: Subject Type: | C10: ='DATA ENTRY'!E14 -> 0
A12: SN | B12: STUDENT ID | C12: STUDENT NAME | D12: QUIZZES | I12: AVERAGE | J12: CLASS STANDING | O12: AVERAGE | P12: MAJOR EXAM | Q12: FINAL GRADE | R12: EQUIVALENT | S12: REMARKS
D13: Quiz 1 | E13: Quiz 2 | F13: Quiz 3 | G13: Quiz 4 | H13: Quiz 5
A14: 1 | B14: ='DATA ENTRY'!B26 -> 24-QC13447 | C14: ='DATA ENTRY'!C26 -> ACOB, TRIXIE JUNIO | D14: 97 | E14: 90 | F14: 85 | I14: =IFERROR(AVERAGE(D14:H14),"0") -> 90.666667 | J14: P | K14: P | L14: P | M14: 94 | O14: =IFERROR(AVERAGE(J14:N14),"0") -> 94 | P14: 94 | Q14: =SUM(I14,O14,P14)/3 -> 92.888889 | R14: =VLOOKUP(Q14,TGQC!$X$1:$Y$990,2) -> 1.5 | S14: =VLOOKUP(R14,TGQC!$H$1:$I$16,2,0) -> Passed
A15: 2 | B15: ='DATA ENTRY'!B27 -> 24-QC12756 | C15: ='DATA ENTRY'!C27 -> ACOSTA, DANNMICHAEL DULLA | D15: 85 | E15: 93 | F15: 100 | I15: =IFERROR(AVERAGE(D15:H15),"0") -> 92.666667 | J15: A | K15: P | L15: A | M15: 90 | O15: =IFERROR(AVERAGE(J15:N15),"0") -> 90 | P15: 90 | Q15: =SUM(I15,O15,P15)/3 -> 90.888889 | R15: =VLOOKUP(Q15,TGQC!$X$1:$Y$990,2) -> 1.75 | S15: =VLOOKUP(R15,TGQC!$H$1:$I$16,2,0) -> Passed
A16: 3 | B16: ='DATA ENTRY'!B28 -> 24-QC12714 | C16: ='DATA ENTRY'!C28 -> AGUILAR, KIMBERLY ASHLEY CALUMPIT | D16: 97 | E16: 100 | F16: 85 | I16: =IFERROR(AVERAGE(D16:H16),"0") -> 94 | J16: P | K16: P | L16: P | M16: 100 | O16: =IFERROR(AVERAGE(J16:N16),"0") -> 100 | P16: 100 | Q16: =SUM(I16,O16,P16)/3 -> 98 | R16: =VLOOKUP(Q16,TGQC!$X$1:$Y$990,2) -> 1 | S16: =VLOOKUP(R16,TGQC!$H$1:$I$16,2,0) -> Passed
A17: 4 | B17: ='DATA ENTRY'!B29 -> 24-QC13807 | C17: ='DATA ENTRY'!C29 -> ARANDIA, JOHN PAUL TAGULAO | D17: 92 | E17: 90 | F17: 85 | I17: =IFERROR(AVERAGE(D17:H17),"0") -> 89 | J17: P | K17: P | L17: P | M17: 94 | O17: =IFERROR(AVERAGE(J17:N17),"0") -> 94 | P17: 94 | Q17: =SUM(I17,O17,P17)/3 -> 92.333333 | R17: =VLOOKUP(Q17,TGQC!$X$1:$Y$990,2) -> 1.5 | S17: =VLOOKUP(R17,TGQC!$H$1:$I$16,2,0) -> Passed
A18: 5 | B18: ='DATA ENTRY'!B30 -> 24-QC13547 | C18: ='DATA ENTRY'!C30 -> AROCHA, NESHANEL | D18: 85 | E18: 90 | F18: 85 | I18: =IFERROR(AVERAGE(D18:H18),"0") -> 86.666667 | J18: P | K18: P | L18: P | M18: 75 | O18: =IFERROR(AVERAGE(J18:N18),"0") -> 75 | P18: 75 | Q18: =SUM(I18,O18,P18)/3 -> 78.888889 | R18: =VLOOKUP(Q18,TGQC!$X$1:$Y$990,2) -> 2.75 | S18: =VLOOKUP(R18,TGQC!$H$1:$I$16,2,0) -> Passed
A19: 6 | B19: ='DATA ENTRY'!B31 -> 24-QC13905 | C19: ='DATA ENTRY'!C31 -> ARRIOLA, GABRIEL PEHID | D19: 92 | E19: 93 | F19: 92 | I19: =IFERROR(AVERAGE(D19:H19),"0") -> 92.333333 | J19: P | K19: P | L19: L | M19: 80 | O19: =IFERROR(AVERAGE(J19:N19),"0") -> 80 | P19: 80 | Q19: =SUM(I19,O19,P19)/3 -> 84.111111 | R19: =VLOOKUP(Q19,TGQC!$X$1:$Y$990,2) -> 2.25 | S19: =VLOOKUP(R19,TGQC!$H$1:$I$16,2,0) -> Passed
A20: 7 | B20: ='DATA ENTRY'!B32 -> 23-QC03433 | C20: ='DATA ENTRY'!C32 -> AVILES, ANTONIO TITOY | D20: 94 | E20: 93 | F20: 70 | I20: =IFERROR(AVERAGE(D20:H20),"0") -> 85.666667 | J20: P | K20: P | L20: A | M20: 90 | O20: =IFERROR(AVERAGE(J20:N20),"0") -> 90 | P20: 90 | Q20: =SUM(I20,O20,P20)/3 -> 88.555556 | R20: =VLOOKUP(Q20,TGQC!$X$1:$Y$990,2) -> 1.75 | S20: =VLOOKUP(R20,TGQC!$H$1:$I$16,2,0) -> Passed
A21: 8 | B21: ='DATA ENTRY'!B33 -> 24-QC12867 | C21: ='DATA ENTRY'!C33 -> BASILIO, CHARLES PLURAL | D21: 97 | E21: 100 | F21: 85 | I21: =IFERROR(AVERAGE(D21:H21),"0") -> 94 | J21: P | K21: P | L21: P | M21: 99 | O21: =IFERROR(AVERAGE(J21:N21),"0") -> 99 | P21: 99 | Q21: =SUM(I21,O21,P21)/3 -> 97.333333 | R21: =VLOOKUP(Q21,TGQC!$X$1:$Y$990,2) -> 1.25 | S21: =VLOOKUP(R21,TGQC!$H$1:$I$16,2,0) -> Passed
A22: 9 | B22: ='DATA ENTRY'!B34 -> 24-QC14612 | C22: ='DATA ENTRY'!C34 -> BRINGINO, RALPH REGOR | D22: 70 | E22: 90 | F22: 70 | I22: =IFERROR(AVERAGE(D22:H22),"0") -> 76.666667 | J22: A | K22: P | L22: A | M22: 90 | O22: =IFERROR(AVERAGE(J22:N22),"0") -> 90 | P22: 90 | Q22: =SUM(I22,O22,P22)/3 -> 85.555556 | R22: =VLOOKUP(Q22,TGQC!$X$1:$Y$990,2) -> 2 | S22: =VLOOKUP(R22,TGQC!$H$1:$I$16,2,0) -> Passed
A23: 10 | B23: ='DATA ENTRY'!B35 -> 24-QC13948 | C23: ='DATA ENTRY'!C35 -> CABRERA, CHARLES IAN | D23: 85 | E23: 95 | F23: 100 | I23: =IFERROR(AVERAGE(D23:H23),"0") -> 93.333333 | J23: P | K23: P | L23: P | M23: 94 | O23: =IFERROR(AVERAGE(J23:N23),"0") -> 94 | P23: 94 | Q23: =SUM(I23,O23,P23)/3 -> 93.777778 | R23: =VLOOKUP(Q23,TGQC!$X$1:$Y$990,2) -> 1.5 | S23: =VLOOKUP(R23,TGQC!$H$1:$I$16,2,0) -> Passed
A24: 11 | B24: ='DATA ENTRY'!B36 -> 24-QC13477 | C24: ='DATA ENTRY'!C36 -> CAMPOS, RYAN MIGUEL PACAYRA | D24: 95 | E24: 90 | F24: 85 | I24: =IFERROR(AVERAGE(D24:H24),"0") -> 90 | J24: P | K24: P | L24: P | M24: 90 | O24: =IFERROR(AVERAGE(J24:N24),"0") -> 90 | P24: 90 | Q24: =SUM(I24,O24,P24)/3 -> 90 | R24: =VLOOKUP(Q24,TGQC!$X$1:$Y$990,2) -> 1.75 | S24: =VLOOKUP(R24,TGQC!$H$1:$I$16,2,0) -> Passed
A25: 12 | B25: ='DATA ENTRY'!B37 -> 24-QC14613 | C25: ='DATA ENTRY'!C37 -> CASTILLO, LOUIS ANGELO CRAME | D25: 95 | E25: 90 | F25: 85 | I25: =IFERROR(AVERAGE(D25:H25),"0") -> 90 | J25: P | K25: P | L25: P | M25: 98 | O25: =IFERROR(AVERAGE(J25:N25),"0") -> 98 | P25: 98 | Q25: =SUM(I25,O25,P25)/3 -> 95.333333 | R25: =VLOOKUP(Q25,TGQC!$X$1:$Y$990,2) -> 1.25 | S25: =VLOOKUP(R25,TGQC!$H$1:$I$16,2,0) -> Passed
... A55: 42 | B55: ='DATA ENTRY'!B67 -> 24-QC13179 | C55: ='DATA ENTRY'!C67 -> VILLAMOR, CHELSEY ANNE | D55: 100 | E55: 100 | F55: 100 | I55: =IFERROR(AVERAGE(D55:H55),"0") -> 100 | J55: P | K55: P | L55: P | M55: 100 | O55: =IFERROR(AVERAGE(J55:N55),"0") -> 100 | P55: 100 | Q55: =SUM(I55,O55,P55)/3 -> 100 | R55: =VLOOKUP(Q55,TGQC!$X$1:$Y$990,2) -> 1 | S55: =VLOOKUP(R55,TGQC!$H$1:$I$16,2,0) -> Passed
A56: 43 | B56: ='DATA ENTRY'!B68 -> 24-QC13435 | C56: ='DATA ENTRY'!C68 -> YABUT, CARYSE AMARA UNTALAN | I56: =IFERROR(AVERAGE(D56:H56),"0") -> 0 | O56: =IFERROR(AVERAGE(J56:N56),"0") -> 0 | Q56: =SUM(I56,O56,P56)/3 -> 0 | R56: =VLOOKUP(Q56,TGQC!$X$1:$Y$990,2) -> #N/A | S56: =VLOOKUP(R56,TGQC!$H$1:$I$16,2,0) -> #N/A
A57: 44 | B57: ='DATA ENTRY'!B69 -> 0 | C57: ='DATA ENTRY'!C69 -> 0 | I57: =IFERROR(AVERAGE(D57:H57),"0") -> 0 | O57: =IFERROR(AVERAGE(J57:N57),"0") -> 0 | Q57: =SUM(I57,O57,P57)/3 -> 0 | R57: =VLOOKUP(Q57,TGQC!$X$1:$Y$990,2) -> #N/A | S57: =VLOOKUP(R57,TGQC!$H$1:$I$16,2,0) -> #N/A
A58: 45 | B58: ='DATA ENTRY'!B70 -> 0 | C58: ='DATA ENTRY'!C70 -> 0 | I58: =IFERROR(AVERAGE(D58:H58),"0") -> 0 | O58: =IFERROR(AVERAGE(J58:N58),"0") -> 0 | Q58: =SUM(I58,O58,P58)/3 -> 0 | R58: =VLOOKUP(Q58,TGQC!$X$1:$Y$990,2) -> #N/A | S58: =VLOOKUP(R58,TGQC!$H$1:$I$16,2,0) -> #N/A
A59: 46 | B59: ='DATA ENTRY'!B71 -> 0 | C59: ='DATA ENTRY'!C71 -> 0 | I59: =IFERROR(AVERAGE(D59:H59),"0") -> 0 | O59: =IFERROR(AVERAGE(J59:N59),"0") -> 0 | Q59: =SUM(I59,O59,P59)/3 -> 0 | R59: =VLOOKUP(Q59,TGQC!$X$1:$Y$990,2) -> #N/A | S59: =VLOOKUP(R59,TGQC!$H$1:$I$16,2,0) -> #N/A
A60: 47 | B60: ='DATA ENTRY'!B72 -> 0 | C60: ='DATA ENTRY'!C72 -> 0 | I60: =IFERROR(AVERAGE(D60:H60),"0") -> 0 | O60: =IFERROR(AVERAGE(J60:N60),"0") -> 0 | Q60: =SUM(I60,O60,P60)/3 -> 0 | R60: =VLOOKUP(Q60,TGQC!$X$1:$Y$990,2) -> #N/A | S60: =VLOOKUP(R60,TGQC!$H$1:$I$16,2,0) -> #N/A
A61: 48 | B61: ='DATA ENTRY'!B73 -> 0 | C61: ='DATA ENTRY'!C73 -> 0 | I61: =IFERROR(AVERAGE(D61:H61),"0") -> 0 | O61: =IFERROR(AVERAGE(J61:N61),"0") -> 0 | Q61: =SUM(I61,O61,P61)/3 -> 0 | R61: =VLOOKUP(Q61,TGQC!$X$1:$Y$990,2) -> #N/A | S61: =VLOOKUP(R61,TGQC!$H$1:$I$16,2,0) -> #N/A
A62: 49 | B62: ='DATA ENTRY'!B74 -> 0 | C62: ='DATA ENTRY'!C74 -> 0 | I62: =IFERROR(AVERAGE(D62:H62),"0") -> 0 | O62: =IFERROR(AVERAGE(J62:N62),"0") -> 0 | Q62: =SUM(I62,O62,P62)/3 -> 0 | R62: =VLOOKUP(Q62,TGQC!$X$1:$Y$990,2) -> #N/A | S62: =VLOOKUP(R62,TGQC!$H$1:$I$16,2,0) -> #N/A
A63: 50 | B63: ='DATA ENTRY'!B75 -> 0 | C63: ='DATA ENTRY'!C75 -> 0 | I63: =IFERROR(AVERAGE(D63:H63),"0") -> 0 | O63: =IFERROR(AVERAGE(J63:N63),"0") -> 0 | Q63: =SUM(I63,O63,P63)/3 -> 0 | R63: =VLOOKUP(Q63,TGQC!$X$1:$Y$990,2) -> #N/A | S63: =VLOOKUP(R63,TGQC!$H$1:$I$16,2,0) -> #N/A
A64: 51 | B64: ='DATA ENTRY'!B76 -> 0 | C64: ='DATA ENTRY'!C76 -> 0 | I64: =IFERROR(AVERAGE(D64:H64),"0") -> 0 | O64: =IFERROR(AVERAGE(J64:N64),"0") -> 0 | Q64: =SUM(I64,O64,P64)/3 -> 0 | R64: =VLOOKUP(Q64,TGQC!$X$1:$Y$990,2) -> #N/A | S64: =VLOOKUP(R64,TGQC!$H$1:$I$16,2,0) -> #N/A
A65: 52 | B65: ='DATA ENTRY'!B77 -> 0 | C65: ='DATA ENTRY'!C77 -> 0 | I65: =IFERROR(AVERAGE(D65:H65),"0") -> 0 | O65: =IFERROR(AVERAGE(J65:N65),"0") -> 0 | Q65: =SUM(I65,O65,P65)/3 -> 0 | R65: =VLOOKUP(Q65,TGQC!$X$1:$Y$990,2) -> #N/A | S65: =VLOOKUP(R65,TGQC!$H$1:$I$16,2,0) -> #N/A
A66: 53 | B66: ='DATA ENTRY'!B78 -> 0 | C66: ='DATA ENTRY'!C78 -> 0 | I66: =IFERROR(AVERAGE(D66:H66),"0") -> 0 | O66: =IFERROR(AVERAGE(J66:N66),"0") -> 0 | Q66: =SUM(I66,O66,P66)/3 -> 0 | R66: =VLOOKUP(Q66,TGQC!$X$1:$Y$990,2) -> #N/A | S66: =VLOOKUP(R66,TGQC!$H$1:$I$16,2,0) -> #N/A
A67: 54 | B67: ='DATA ENTRY'!B79 -> 0 | C67: ='DATA ENTRY'!C79 -> 0 | I67: =IFERROR(AVERAGE(D67:H67),"0") -> 0 | O67: =IFERROR(AVERAGE(J67:N67),"0") -> 0 | Q67: =SUM(I67,O67,P67)/3 -> 0 | R67: =VLOOKUP(Q67,TGQC!$X$1:$Y$990,2) -> #N/A | S67: =VLOOKUP(R67,TGQC!$H$1:$I$16,2,0) -> #N/A
... A113: 100 | B113: ='DATA ENTRY'!B125 -> 0 | C113: ='DATA ENTRY'!C125 -> 0 | I113: =IFERROR(AVERAGE(D113:H113),"0") -> 0 | O113: =IFERROR(AVERAGE(J113:N113),"0") -> 0 | Q113: =SUM(I113,O113,P113)/3 -> 0 | R113: =VLOOKUP(Q113,TGQC!$X$1:$Y$990,2) -> #N/A | S113: =VLOOKUP(R113,TGQC!$H$1:$I$16,2,0) -> #N/A

Sheet MIDTERM
A1: WORLD CITI COLLEGES
A2: ='DATA ENTRY'!E6 -> Antipolo City
A3: CLASS RECORD
A4: MIDTERM PERIOD
B5: Intsructor: | C5: ='DATA ENTRY'!$E$9 -> 0 | J5: Day: | K5: ='DATA ENTRY'!$C$18 -> 0 | P5: Unit: | Q5: ='DATA ENTRY'!C21 -> 0
B6: ='DATA ENTRY'!D10 -> DEAN | C6: ='DATA ENTRY'!$E$10 -> 0 | J6: Time: | K6: ='DATA ENTRY'!$C$19 -> 0 | P6: Year & Sec: | Q6: ='DATA ENTRY'!E13 -> 0
B7: Department: | C7: ='DATA ENTRY'!$C$11 -> 0 | J7: Room: | K7: ='DATA ENTRY'!C20 -> 0
B8: Course Code: | C8: ='DATA ENTRY'!$C$12 -> 0 | J8: Semester: | K8: ='DATA ENTRY'!C10 -> 0
B9: Course Description: | C9: ='DATA ENTRY'!$C$13 -> 0
B10: Subject Type: | C10: ='DATA ENTRY'!E14 -> 0
A12: SN | B12: STUDENT ID | C12: STUDENT NAME | D12: QUIZZES | I12: AVERAGE | J12: CLASS STANDING | O12: AVERAGE | P12: MAJOR EXAM | Q12: FINAL GRADE | R12: EQUIVALENT | S12: REMARKS
D13: Quiz 1 | E13: Quiz 2 | F13: Quiz 3 | G13: Quiz 4 | H13: Quiz 5
A14: 1 | B14: ='DATA ENTRY'!B26 -> 24-QC13447 | C14: ='DATA ENTRY'!C26 -> ACOB, TRIXIE JUNIO | E14: 85 | I14: =IFERROR(AVERAGE(D14:H14),"0") -> 85 | J14: P | K14: P | L14: P | M14: 90 | O14: =IFERROR(AVERAGE(J14:N14),"0") -> 90 | P14: 90 | Q14: =SUM(I14,O14,P14)/3 -> 88.333333 | R14: =VLOOKUP(Q14,TGQC!$X$1:$Y$990,2) -> 2 | S14: =VLOOKUP(R14,TGQC!$H$1:$I$16,2,0) -> Passed
A15: 2 | B15: ='DATA ENTRY'!B27 -> 24-QC12756 | C15: ='DATA ENTRY'!C27 -> ACOSTA, DANNMICHAEL DULLA | E15: 85 | I15: =IFERROR(AVERAGE(D15:H15),"0") -> 85 | J15: P | K15: P | L15: P | M15: 80 | O15: =IFERROR(AVERAGE(J15:N15),"0") -> 80 | P15: 80 | Q15: =SUM(I15,O15,P15)/3 -> 81.666667 | R15: =VLOOKUP(Q15,TGQC!$X$1:$Y$990,2) -> 2.5 | S15: =VLOOKUP(R15,TGQC!$H$1:$I$16,2,0) -> Passed
A16: 3 | B16: ='DATA ENTRY'!B28 -> 24-QC12714 | C16: ='DATA ENTRY'!C28 -> AGUILAR, KIMBERLY ASHLEY CALUMPIT | E16: 94 | I16: =IFERROR(AVERAGE(D16:H16),"0") -> 94 | J16: P | K16: P | L16: P | M16: 100 | O16: =IFERROR(AVERAGE(J16:N16),"0") -> 100 | P16: 100 | Q16: =SUM(I16,O16,P16)/3 -> 98 | R16: =VLOOKUP(Q16,TGQC!$X$1:$Y$990,2) -> 1 | S16: =VLOOKUP(R16,TGQC!$H$1:$I$16,2,0) -> Passed
A17: 4 | B17: ='DATA ENTRY'!B29 -> 24-QC13807 | C17: ='DATA ENTRY'!C29 -> ARANDIA, JOHN PAUL TAGULAO | E17: 90 | I17: =IFERROR(AVERAGE(D17:H17),"0") -> 90 | J17: P | K17: P | L17: P | M17: 90 | O17: =IFERROR(AVERAGE(J17:N17),"0") -> 90 | P17: 90 | Q17: =SUM(I17,O17,P17)/3 -> 90 | R17: =VLOOKUP(Q17,TGQC!$X$1:$Y$990,2) -> 1.75 | S17: =VLOOKUP(R17,TGQC!$H$1:$I$16,2,0) -> Passed
A18: 5 | B18: ='DATA ENTRY'!B30 -> 24-QC13547 | C18: ='DATA ENTRY'!C30 -> AROCHA, NESHANEL | E18: 80 | I18: =IFERROR(AVERAGE(D18:H18),"0") -> 80 | J18: P | K18: A | L18: P | M18: 80 | O18: =IFERROR(AVERAGE(J18:N18),"0") -> 80 | P18: 80 | Q18: =SUM(I18,O18,P18)/3 -> 80 | R18: =VLOOKUP(Q18,TGQC!$X$1:$Y$990,2) -> 2.5 | S18: =VLOOKUP(R18,TGQC!$H$1:$I$16,2,0) -> Passed
A19: 6 | B19: ='DATA ENTRY'!B31 -> 24-QC13905 | C19: ='DATA ENTRY'!C31 -> ARRIOLA, GABRIEL PEHID | E19: 90 | I19: =IFERROR(AVERAGE(D19:H19),"0") -> 90 | J19: P | K19: P | L19: A | M19: 100 | O19: =IFERROR(AVERAGE(J19:N19),"0") -> 100 | P19: 100 | Q19: =SUM(I19,O19,P19)/3 -> 96.666667 | R19: =VLOOKUP(Q19,TGQC!$X$1:$Y$990,2) -> 1.25 | S19: =VLOOKUP(R19,TGQC!$H$1:$I$16,2,0) -> Passed
A20: 7 | B20: ='DATA ENTRY'!B32 -> 23-QC03433 | C20: ='DATA ENTRY'!C32 -> AVILES, ANTONIO TITOY | E20: 85 | I20: =IFERROR(AVERAGE(D20:H20),"0") -> 85 | J20: A | K20: P | L20: A | M20: 100 | O20: =IFERROR(AVERAGE(J20:N20),"0") -> 100 | P20: 100 | Q20: =SUM(I20,O20,P20)/3 -> 95 | R20: =VLOOKUP(Q20,TGQC!$X$1:$Y$990,2) -> 1.25 | S20: =VLOOKUP(R20,TGQC!$H$1:$I$16,2,0) -> Passed
A21: 8 | B21: ='DATA ENTRY'!B33 -> 24-QC12867 | C21: ='DATA ENTRY'!C33 -> BASILIO, CHARLES PLURAL | E21: 94 | I21: =IFERROR(AVERAGE(D21:H21),"0") -> 94 | J21: P | K21: P | L21: P | M21: 100 | O21: =IFERROR(AVERAGE(J21:N21),"0") -> 100 | P21: 100 | Q21: =SUM(I21,O21,P21)/3 -> 98 | R21: =VLOOKUP(Q21,TGQC!$X$1:$Y$990,2) -> 1 | S21: =VLOOKUP(R21,TGQC!$H$1:$I$16,2,0) -> Passed
A22: 9 | B22: ='DATA ENTRY'!B34 -> 24-QC14612 | C22: ='DATA ENTRY'!C34 -> BRINGINO, RALPH REGOR | E22: 80 | I22: =IFERROR(AVERAGE(D22:H22),"0") -> 80 | J22: P | K22: P | L22: A | M22: 100 | O22: =IFERROR(AVERAGE(J22:N22),"0") -> 100 | P22: 100 | Q22: =SUM(I22,O22,P22)/3 -> 93.333333 | R22: =VLOOKUP(Q22,TGQC!$X$1:$Y$990,2) -> 1.5 | S22: =VLOOKUP(R22,TGQC!$H$1:$I$16,2,0) -> Passed
A23: 10 | B23: ='DATA ENTRY'!B35 -> 24-QC13948 | C23: ='DATA ENTRY'!C35 -> CABRERA, CHARLES IAN | E23: 90 | I23: =IFERROR(AVERAGE(D23:H23),"0") -> 90 | J23: P | K23: P | L23: P | M23: 100 | O23: =IFERROR(AVERAGE(J23:N23),"0") -> 100 | P23: 100 | Q23: =SUM(I23,O23,P23)/3 -> 96.666667 | R23: =VLOOKUP(Q23,TGQC!$X$1:$Y$990,2) -> 1.25 | S23: =VLOOKUP(R23,TGQC!$H$1:$I$16,2,0) -> Passed
A24: 11 | B24: ='DATA ENTRY'!B36 -> 24-QC13477 | C24: ='DATA ENTRY'!C36 -> CAMPOS, RYAN MIGUEL PACAYRA | E24: 60 | I24: =IFERROR(AVERAGE(D24:H24),"0") -> 60 | J24: P | K24: P | L24: A | M24: 60 | O24: =IFERROR(AVERAGE(J24:N24),"0") -> 60 | P24: 60 | Q24: =SUM(I24,O24,P24)/3 -> 60 | R24: =VLOOKUP(Q24,TGQC!$X$1:$Y$990,2) -> 5 | S24: =VLOOKUP(R24,TGQC!$H$1:$I$16,2,0) -> Failed
A25: 12 | B25: ='DATA ENTRY'!B37 -> 24-QC14613 | C25: ='DATA ENTRY'!C37 -> CASTILLO, LOUIS ANGELO CRAME | E25: 94 | I25: =IFERROR(AVERAGE(D25:H25),"0") -> 94 | J25: P | K25: P | L25: P | M25: 90 | O25: =IFERROR(AVERAGE(J25:N25),"0") -> 90 | P25: 90 | Q25: =SUM(I25,O25,P25)/3 -> 91.333333 | R25: =VLOOKUP(Q25,TGQC!$X$1:$Y$990,2) -> 1.75 | S25: =VLOOKUP(R25,TGQC!$H$1:$I$16,2,0) -> Passed
... A55: 42 | B55: ='DATA ENTRY'!B67 -> 24-QC13179 | C55: ='DATA ENTRY'!C67 -> VILLAMOR, CHELSEY ANNE | E55: 95 | I55: =IFERROR(AVERAGE(D55:H55),"0") -> 95 | J55: P | K55: P | L55: P | M55: 100 | O55: =IFERROR(AVERAGE(J55:N55),"0") -> 100 | P55: 100 | Q55: =SUM(I55,O55,P55)/3 -> 98.333333 | R55: =VLOOKUP(Q55,TGQC!$X$1:$Y$990,2) -> 1 | S55: =VLOOKUP(R55,TGQC!$H$1:$I$16,2,0) -> Passed
A56: 43 | B56: ='DATA ENTRY'!B68 -> 24-QC13435 | C56: ='DATA ENTRY'!C68 -> YABUT, CARYSE AMARA UNTALAN | E56: 100 | I56: =IFERROR(AVERAGE(D56:H56),"0") -> 100 | M56: 100 | O56: =IFERROR(AVERAGE(J56:N56),"0") -> 100 | P56: 100 | Q56: =SUM(I56,O56,P56)/3 -> 100 | R56: =VLOOKUP(Q56,TGQC!$X$1:$Y$990,2) -> 1 | S56: =VLOOKUP(R56,TGQC!$H$1:$I$16,2,0) -> Passed
A57: 44 | B57: ='DATA ENTRY'!B69 -> 0 | C57: ='DATA ENTRY'!C69 -> 0 | I57: =IFERROR(AVERAGE(D57:H57),"0") -> 0 | O57: =IFERROR(AVERAGE(J57:N57),"0") -> 0 | Q57: =SUM(I57,O57,P57)/3 -> 0 | R57: =VLOOKUP(Q57,TGQC!$X$1:$Y$990,2) -> #N/A | S57: =VLOOKUP(R57,TGQC!$H$1:$I$16,2,0) -> #N/A
A58: 45 | B58: ='DATA ENTRY'!B70 -> 0 | C58: ='DATA ENTRY'!C70 -> 0 | I58: =IFERROR(AVERAGE(D58:H58),"0") -> 0 | O58: =IFERROR(AVERAGE(J58:N58),"0") -> 0 | Q58: =SUM(I58,O58,P58)/3 -> 0 | R58: =VLOOKUP(Q58,TGQC!$X$1:$Y$990,2) -> #N/A | S58: =VLOOKUP(R58,TGQC!$H$1:$I$16,2,0) -> #N/A
A59: 46 | B59: ='DATA ENTRY'!B71 -> 0 | C59: ='DATA ENTRY'!C71 -> 0 | I59: =IFERROR(AVERAGE(D59:H59),"0") -> 0 | O59: =IFERROR(AVERAGE(J59:N59),"0") -> 0 | Q59: =SUM(I59,O59,P59)/3 -> 0 | R59: =VLOOKUP(Q59,TGQC!$X$1:$Y$990,2) -> #N/A | S59: =VLOOKUP(R59,TGQC!$H$1:$I$16,2,0) -> #N/A
A60: 47 | B60: ='DATA ENTRY'!B72 -> 0 | C60: ='DATA ENTRY'!C72 -> 0 | I60: =IFERROR(AVERAGE(D60:H60),"0") -> 0 | O60: =IFERROR(AVERAGE(J60:N60),"0") -> 0 | Q60: =SUM(I60,O60,P60)/3 -> 0 | R60: =VLOOKUP(Q60,TGQC!$X$1:$Y$990,2) -> #N/A | S60: =VLOOKUP(R60,TGQC!$H$1:$I$16,2,0) -> #N/A
A61: 48 | B61: ='DATA ENTRY'!B73 -> 0 | C61: ='DATA ENTRY'!C73 -> 0 | I61: =IFERROR(AVERAGE(D61:H61),"0") -> 0 | O61: =IFERROR(AVERAGE(J61:N61),"0") -> 0 | Q61: =SUM(I61,O61,P61)/3 -> 0 | R61: =VLOOKUP(Q61,TGQC!$X$1:$Y$990,2) -> #N/A | S61: =VLOOKUP(R61,TGQC!$H$1:$I$16,2,0) -> #N/A
A62: 49 | B62: ='DATA ENTRY'!B74 -> 0 | C62: ='DATA ENTRY'!C74 -> 0 | I62: =IFERROR(AVERAGE(D62:H62),"0") -> 0 | O62: =IFERROR(AVERAGE(J62:N62),"0") -> 0 | Q62: =SUM(I62,O62,P62)/3 -> 0 | R62: =VLOOKUP(Q62,TGQC!$X$1:$Y$990,2) -> #N/A | S62: =VLOOKUP(R62,TGQC!$H$1:$I$16,2,0) -> #N/A
A63: 50 | B63: ='DATA ENTRY'!B75 -> 0 | C63: ='DATA ENTRY'!C75 -> 0 | I63: =IFERROR(AVERAGE(D63:H63),"0") -> 0 | O63: =IFERROR(AVERAGE(J63:N63),"0") -> 0 | Q63: =SUM(I63,O63,P63)/3 -> 0 | R63: =VLOOKUP(Q63,TGQC!$X$1:$Y$990,2) -> #N/A | S63: =VLOOKUP(R63,TGQC!$H$1:$I$16,2,0) -> #N/A
A64: 51 | B64: ='DATA ENTRY'!B76 -> 0 | C64: ='DATA ENTRY'!C76 -> 0 | I64: =IFERROR(AVERAGE(D64:H64),"0") -> 0 | O64: =IFERROR(AVERAGE(J64:N64),"0") -> 0 | Q64: =SUM(I64,O64,P64)/3 -> 0 | R64: =VLOOKUP(Q64,TGQC!$X$1:$Y$990,2) -> #N/A | S64: =VLOOKUP(R64,TGQC!$H$1:$I$16,2,0) -> #N/A
A65: 52 | B65: ='DATA ENTRY'!B77 -> 0 | C65: ='DATA ENTRY'!C77 -> 0 | I65: =IFERROR(AVERAGE(D65:H65),"0") -> 0 | O65: =IFERROR(AVERAGE(J65:N65),"0") -> 0 | Q65: =SUM(I65,O65,P65)/3 -> 0 | R65: =VLOOKUP(Q65,TGQC!$X$1:$Y$990,2) -> #N/A | S65: =VLOOKUP(R65,TGQC!$H$1:$I$16,2,0) -> #N/A
A66: 53 | B66: ='DATA ENTRY'!B78 -> 0 | C66: ='DATA ENTRY'!C78 -> 0 | I66: =IFERROR(AVERAGE(D66:H66),"0") -> 0 | O66: =IFERROR(AVERAGE(J66:N66),"0") -> 0 | Q66: =SUM(I66,O66,P66)/3 -> 0 | R66: =VLOOKUP(Q66,TGQC!$X$1:$Y$990,2) -> #N/A | S66: =VLOOKUP(R66,TGQC!$H$1:$I$16,2,0) -> #N/A
A67: 54 | B67: ='DATA ENTRY'!B79 -> 0 | C67: ='DATA ENTRY'!C79 -> 0 | I67: =IFERROR(AVERAGE(D67:H67),"0") -> 0 | O67: =IFERROR(AVERAGE(J67:N67),"0") -> 0 | Q67: =SUM(I67,O67,P67)/3 -> 0 | R67: =VLOOKUP(Q67,TGQC!$X$1:$Y$990,2) -> #N/A | S67: =VLOOKUP(R67,TGQC!$H$1:$I$16,2,0) -> #N/A
A68: 55 | B68: ='DATA ENTRY'!B80 -> 0 | C68: ='DATA ENTRY'!C80 -> 0 | I68: =IFERROR(AVERAGE(D68:H68),"0") -> 0 | O68: =IFERROR(AVERAGE(J68:N68),"0") -> 0 | Q68: =SUM(I68,O68,P68)/3 -> 0 | R68: =VLOOKUP(Q68,TGQC!$X$1:$Y$990,2) -> #N/A | S68: =VLOOKUP(R68,TGQC!$H$1:$I$16,2,0) -> #N/A
... A113: 100 | B113: ='DATA ENTRY'!B125 -> 0 | C113: ='DATA ENTRY'!C125 -> 0 | I113: =IFERROR(AVERAGE(D113:H113),"0") -> 0 | O113: =IFERROR(AVERAGE(J113:N113),"0") -> 0 | Q113: =SUM(I113,O113,P113)/3 -> 0 | R113: =VLOOKUP(Q113,TGQC!$X$1:$Y$990,2) -> #N/A | S113: =VLOOKUP(R113,TGQC!$H$1:$I$16,2,0) -> #N/A

Sheet FINAL
A1: WORLD CITI COLLEGES
A2: ='DATA ENTRY'!E6 -> Antipolo City
A3: CLASS RECORD
A4: FINAL PERIOD
B5: Intsructor: | C5: ='DATA ENTRY'!$E$9 -> 0 | J5: Day: | K5: ='DATA ENTRY'!$C$18 -> 0 | P5: Unit: | Q5: ='DATA ENTRY'!C21 -> 0
B6: ='DATA ENTRY'!D10 -> DEAN | C6: ='DATA ENTRY'!$E$10 -> 0 | J6: Time: | K6: ='DATA ENTRY'!$C$19 -> 0 | P6: Year & Sec: | Q6: ='DATA ENTRY'!E13 -> 0
B7: Department: | C7: ='DATA ENTRY'!$C$11 -> 0 | J7: Room: | K7: ='DATA ENTRY'!C20 -> 0
B8: Course Code: | C8: ='DATA ENTRY'!$C$12 -> 0 | J8: Semester: | K8: ='DATA ENTRY'!C10 -> 0
B9: Course Description: | C9: ='DATA ENTRY'!$C$13 -> 0
B10: Subject Type: | C10: ='DATA ENTRY'!E14 -> 0
A12: SN | B12: STUDENT ID | C12: STUDENT NAME | D12: QUIZZES | I12: AVERAGE | J12: CLASS STANDING | O12: AVERAGE | P12: MAJOR EXAM | Q12: FINAL GRADE | R12: EQUIVALENT | S12: REMARKS | T12: STUDENT MARKING
D13: Quiz 1 | E13: Quiz 2 | F13: Quiz 3 | G13: Quiz 4 | H13: Quiz 5
A14: 1 | B14: ='DATA ENTRY'!B26 -> 24-QC13447 | C14: ='DATA ENTRY'!C26 -> ACOB, TRIXIE JUNIO | D14: 95 | I14: =IFERROR(AVERAGE(D14:H14),"0") -> 95 | J14: P | K14: P | L14: 92 | O14: =IFERROR(AVERAGE(J14:N14),"0") -> 92 | P14: 92 | Q14: =SUM(I14,O14,P14)/3 -> 93 | R14: =IFERROR(VLOOKUP(Q14,TGQC!$X$1:$Y$990,2),"0") -> 1.5 | S14: =VLOOKUP(R14&"-"&T14,TGQC!$N$1:$Q$56,4,0) -> Passed
A15: 2 | B15: ='DATA ENTRY'!B27 -> 24-QC12756 | C15: ='DATA ENTRY'!C27 -> ACOSTA, DANNMICHAEL DULLA | D15: 80 | I15: =IFERROR(AVERAGE(D15:H15),"0") -> 80 | J15: A | K15: A | L15: 95 | O15: =IFERROR(AVERAGE(J15:N15),"0") -> 95 | P15: 95 | Q15: =SUM(I15,O15,P15)/3 -> 90 | R15: =IFERROR(VLOOKUP(Q15,TGQC!$X$1:$Y$990,2),"0") -> 1.75 | S15: =VLOOKUP(R15&"-"&T15,TGQC!$N$1:$Q$56,4,0) -> Passed
A16: 3 | B16: ='DATA ENTRY'!B28 -> 24-QC12714 | C16: ='DATA ENTRY'!C28 -> AGUILAR, KIMBERLY ASHLEY CALUMPIT | D16: 95 | I16: =IFERROR(AVERAGE(D16:H16),"0") -> 95 | J16: P | K16: P | L16: 100 | O16: =IFERROR(AVERAGE(J16:N16),"0") -> 100 | P16: 100 | Q16: =SUM(I16,O16,P16)/3 -> 98.333333 | R16: =IFERROR(VLOOKUP(Q16,TGQC!$X$1:$Y$990,2),"0") -> 1 | S16: =VLOOKUP(R16&"-"&T16,TGQC!$N$1:$Q$56,4,0) -> Passed
A17: 4 | B17: ='DATA ENTRY'!B29 -> 24-QC13807 | C17: ='DATA ENTRY'!C29 -> ARANDIA, JOHN PAUL TAGULAO | D17: 95 | I17: =IFERROR(AVERAGE(D17:H17),"0") -> 95 | J17: P | K17: P | L17: 95 | O17: =IFERROR(AVERAGE(J17:N17),"0") -> 95 | P17: 95 | Q17: =SUM(I17,O17,P17)/3 -> 95 | R17: =IFERROR(VLOOKUP(Q17,TGQC!$X$1:$Y$990,2),"0") -> 1.25 | S17: =VLOOKUP(R17&"-"&T17,TGQC!$N$1:$Q$56,4,0) -> Passed
A18: 5 | B18: ='DATA ENTRY'!B30 -> 24-QC13547 | C18: ='DATA ENTRY'!C30 -> AROCHA, NESHANEL | D18: 85 | I18: =IFERROR(AVERAGE(D18:H18),"0") -> 85 | J18: A | K18: P | L18: 85 | O18: =IFERROR(AVERAGE(J18:N18),"0") -> 85 | P18: 85 | Q18: =SUM(I18,O18,P18)/3 -> 85 | R18: =IFERROR(VLOOKUP(Q18,TGQC!$X$1:$Y$990,2),"0") -> 2.25 | S18: =VLOOKUP(R18&"-"&T18,TGQC!$N$1:$Q$56,4,0) -> Passed
A19: 6 | B19: ='DATA ENTRY'!B31 -> 24-QC13905 | C19: ='DATA ENTRY'!C31 -> ARRIOLA, GABRIEL PEHID | D19: 85 | I19: =IFERROR(AVERAGE(D19:H19),"0") -> 85 | J19: A | K19: P | L19: 92 | O19: =IFERROR(AVERAGE(J19:N19),"0") -> 92 | P19: 92 | Q19: =SUM(I19,O19,P19)/3 -> 89.666667 | R19: =IFERROR(VLOOKUP(Q19,TGQC!$X$1:$Y$990,2),"0") -> 1.75 | S19: =VLOOKUP(R19&"-"&T19,TGQC!$N$1:$Q$56,4,0) -> Passed
A20: 7 | B20: ='DATA ENTRY'!B32 -> 23-QC03433 | C20: ='DATA ENTRY'!C32 -> AVILES, ANTONIO TITOY | D20: 80 | I20: =IFERROR(AVERAGE(D20:H20),"0") -> 80 | J20: A | K20: A | L20: 92 | O20: =IFERROR(AVERAGE(J20:N20),"0") -> 92 | P20: 92 | Q20: =SUM(I20,O20,P20)/3 -> 88 | R20: =IFERROR(VLOOKUP(Q20,TGQC!$X$1:$Y$990,2),"0") -> 2 | S20: =VLOOKUP(R20&"-"&T20,TGQC!$N$1:$Q$56,4,0) -> Passed
A21: 8 | B21: ='DATA ENTRY'!B33 -> 24-QC12867 | C21: ='DATA ENTRY'!C33 -> BASILIO, CHARLES PLURAL | D21: 95 | I21: =IFERROR(AVERAGE(D21:H21),"0") -> 95 | J21: P | K21: P | L21: 99 | O21: =IFERROR(AVERAGE(J21:N21),"0") -> 99 | P21: 99 | Q21: =SUM(I21,O21,P21)/3 -> 97.666667 | R21: =IFERROR(VLOOKUP(Q21,TGQC!$X$1:$Y$990,2),"0") -> 1 | S21: =VLOOKUP(R21&"-"&T21,TGQC!$N$1:$Q$56,4,0) -> Passed
A22: 9 | B22: ='DATA ENTRY'!B34 -> 24-QC14612 | C22: ='DATA ENTRY'!C34 -> BRINGINO, RALPH REGOR | D22: 80 | I22: =IFERROR(AVERAGE(D22:H22),"0") -> 80 | J22: A | K22: A | L22: 92 | O22: =IFERROR(AVERAGE(J22:N22),"0") -> 92 | P22: 92 | Q22: =SUM(I22,O22,P22)/3 -> 88 | R22: =IFERROR(VLOOKUP(Q22,TGQC!$X$1:$Y$990,2),"0") -> 2 | S22: =VLOOKUP(R22&"-"&T22,TGQC!$N$1:$Q$56,4,0) -> Passed
A23: 10 | B23: ='DATA ENTRY'!B35 -> 24-QC13948 | C23: ='DATA ENTRY'!C35 -> CABRERA, CHARLES IAN | D23: 85 | I23: =IFERROR(AVERAGE(D23:H23),"0") -> 85 | J23: A | K23: P | L23: 95 | O23: =IFERROR(AVERAGE(J23:N23),"0") -> 95 | P23: 95 | Q23: =SUM(I23,O23,P23)/3 -> 91.666667 | R23: =IFERROR(VLOOKUP(Q23,TGQC!$X$1:$Y$990,2),"0") -> 1.5 | S23: =VLOOKUP(R23&"-"&T23,TGQC!$N$1:$Q$56,4,0) -> Passed
A24: 11 | B24: ='DATA ENTRY'!B36 -> 24-QC13477 | C24: ='DATA ENTRY'!C36 -> CAMPOS, RYAN MIGUEL PACAYRA | D24: 69 | I24: =IFERROR(AVERAGE(D24:H24),"0") -> 69 | J24: A | K24: A | L24: 69 | O24: =IFERROR(AVERAGE(J24:N24),"0") -> 69 | P24: 69 | Q24: =SUM(I24,O24,P24)/3 -> 69 | R24: =IFERROR(VLOOKUP(Q24,TGQC!$X$1:$Y$990,2),"0") -> 5 | S24: =VLOOKUP(R24&"-"&T24,TGQC!$N$1:$Q$56,4,0) -> Failed
A25: 12 | B25: ='DATA ENTRY'!B37 -> 24-QC14613 | C25: ='DATA ENTRY'!C37 -> CASTILLO, LOUIS ANGELO CRAME | D25: 85 | I25: =IFERROR(AVERAGE(D25:H25),"0") -> 85 | J25: A | K25: P | L25: 95 | O25: =IFERROR(AVERAGE(J25:N25),"0") -> 95 | P25: 95 | Q25: =SUM(I25,O25,P25)/3 -> 91.666667 | R25: =IFERROR(VLOOKUP(Q25,TGQC!$X$1:$Y$990,2),"0") -> 1.5 | S25: =VLOOKUP(R25&"-"&T25,TGQC!$N$1:$Q$56,4,0) -> Passed
... A56: 43 | B56: ='DATA ENTRY'!B68 -> 24-QC13435 | C56: ='DATA ENTRY'!C68 -> YABUT, CARYSE AMARA UNTALAN | D56: 95 | I56: =IFERROR(AVERAGE(D56:H56),"0") -> 95 | J56: P | K56: P | L56: 98 | O56: =IFERROR(AVERAGE(J56:N56),"0") -> 98 | P56: 98 | Q56: =SUM(I56,O56,P56)/3 -> 97 | R56: =IFERROR(VLOOKUP(Q56,TGQC!$X$1:$Y$990,2),"0") -> 1.25 | S56: =VLOOKUP(R56&"-"&T56,TGQC!$N$1:$Q$56,4,0) -> Passed
A57: 44 | B57: ='DATA ENTRY'!B69 -> 0 | C57: ='DATA ENTRY'!C69 -> 0 | I57: =IFERROR(AVERAGE(D57:H57),"0") -> 0 | O57: =IFERROR(AVERAGE(J57:N57),"0") -> 0 | Q57: =SUM(I57,O57,P57)/3 -> 0 | R57: =IFERROR(VLOOKUP(Q57,TGQC!$X$1:$Y$990,2),"0") -> 0 | S57: =VLOOKUP(R57&"-"&T57,TGQC!$N$1:$Q$56,4,0) -> Failed
A58: 45 | B58: ='DATA ENTRY'!B70 -> 0 | C58: ='DATA ENTRY'!C70 -> 0 | I58: =IFERROR(AVERAGE(D58:H58),"0") -> 0 | O58: =IFERROR(AVERAGE(J58:N58),"0") -> 0 | Q58: =SUM(I58,O58,P58)/3 -> 0 | R58: =IFERROR(VLOOKUP(Q58,TGQC!$X$1:$Y$990,2),"0") -> 0 | S58: =VLOOKUP(R58&"-"&T58,TGQC!$N$1:$Q$56,4,0) -> Failed
A59: 46 | B59: ='DATA ENTRY'!B71 -> 0 | C59: ='DATA ENTRY'!C71 -> 0 | I59: =IFERROR(AVERAGE(D59:H59),"0") -> 0 | O59: =IFERROR(AVERAGE(J59:N59),"0") -> 0 | Q59: =SUM(I59,O59,P59)/3 -> 0 | R59: =IFERROR(VLOOKUP(Q59,TGQC!$X$1:$Y$990,2),"0") -> 0 | S59: =VLOOKUP(R59&"-"&T59,TGQC!$N$1:$Q$56,4,0) -> Failed
A60: 47 | B60: ='DATA ENTRY'!B72 -> 0 | C60: ='DATA ENTRY'!C72 -> 0 | I60: =IFERROR(AVERAGE(D60:H60),"0") -> 0 | O60: =IFERROR(AVERAGE(J60:N60),"0") -> 0 | Q60: =SUM(I60,O60,P60)/3 -> 0 | R60: =IFERROR(VLOOKUP(Q60,TGQC!$X$1:$Y$990,2),"0") -> 0 | S60: =VLOOKUP(R60&"-"&T60,TGQC!$N$1:$Q$56,4,0) -> Failed
A61: 48 | B61: ='DATA ENTRY'!B73 -> 0 | C61: ='DATA ENTRY'!C73 -> 0 | I61: =IFERROR(AVERAGE(D61:H61),"0") -> 0 | O61: =IFERROR(AVERAGE(J61:N61),"0") -> 0 | Q61: =SUM(I61,O61,P61)/3 -> 0 | R61: =IFERROR(VLOOKUP(Q61,TGQC!$X$1:$Y$990,2),"0") -> 0 | S61: =VLOOKUP(R61&"-"&T61,TGQC!$N$1:$Q$56,4,0) -> Failed
A62: 49 | B62: ='DATA ENTRY'!B74 -> 0 | C62: ='DATA ENTRY'!C74 -> 0 | I62: =IFERROR(AVERAGE(D62:H62),"0") -> 0 | O62: =IFERROR(AVERAGE(J62:N62),"0") -> 0 | Q62: =SUM(I62,O62,P62)/3 -> 0 | R62: =IFERROR(VLOOKUP(Q62,TGQC!$X$1:$Y$990,2),"0") -> 0 | S62: =VLOOKUP(R62&"-"&T62,TGQC!$N$1:$Q$56,4,0) -> Failed
A63: 50 | B63: ='DATA ENTRY'!B75 -> 0 | C63: ='DATA ENTRY'!C75 -> 0 | I63: =IFERROR(AVERAGE(D63:H63),"0") -> 0 | O63: =IFERROR(AVERAGE(J63:N63),"0") -> 0 | Q63: =SUM(I63,O63,P63)/3 -> 0 | R63: =IFERROR(VLOOKUP(Q63,TGQC!$X$1:$Y$990,2),"0") -> 0 | S63: =VLOOKUP(R63&"-"&T63,TGQC!$N$1:$Q$56,4,0) -> Failed
A64: 51 | B64: ='DATA ENTRY'!B76 -> 0 | C64: ='DATA ENTRY'!C76 -> 0 | I64: =IFERROR(AVERAGE(D64:H64),"0") -> 0 | O64: =IFERROR(AVERAGE(J64:N64),"0") -> 0 | Q64: =SUM(I64,O64,P64)/3 -> 0 | R64: =IFERROR(VLOOKUP(Q64,TGQC!$X$1:$Y$990,2),"0") -> 0 | S64: =VLOOKUP(R64&"-"&T64,TGQC!$N$1:$Q$56,4,0) -> Failed
A65: 52 | B65: ='DATA ENTRY'!B77 -> 0 | C65: ='DATA ENTRY'!C77 -> 0 | I65: =IFERROR(AVERAGE(D65:H65),"0") -> 0 | O65: =IFERROR(AVERAGE(J65:N65),"0") -> 0 | Q65: =SUM(I65,O65,P65)/3 -> 0 | R65: =IFERROR(VLOOKUP(Q65,TGQC!$X$1:$Y$990,2),"0") -> 0 | S65: =VLOOKUP(R65&"-"&T65,TGQC!$N$1:$Q$56,4,0) -> Failed
A66: 53 | B66: ='DATA ENTRY'!B78 -> 0 | C66: ='DATA ENTRY'!C78 -> 0 | I66: =IFERROR(AVERAGE(D66:H66),"0") -> 0 | O66: =IFERROR(AVERAGE(J66:N66),"0") -> 0 | Q66: =SUM(I66,O66,P66)/3 -> 0 | R66: =IFERROR(VLOOKUP(Q66,TGQC!$X$1:$Y$990,2),"0") -> 0 | S66: =VLOOKUP(R66&"-"&T66,TGQC!$N$1:$Q$56,4,0) -> Failed
A67: 54 | B67: ='DATA ENTRY'!B79 -> 0 | C67: ='DATA ENTRY'!C79 -> 0 | I67: =IFERROR(AVERAGE(D67:H67),"0") -> 0 | O67: =IFERROR(AVERAGE(J67:N67),"0") -> 0 | Q67: =SUM(I67,O67,P67)/3 -> 0 | R67: =IFERROR(VLOOKUP(Q67,TGQC!$X$1:$Y$990,2),"0") -> 0 | S67: =VLOOKUP(R67&"-"&T67,TGQC!$N$1:$Q$56,4,0) -> Failed
A68: 55 | B68: ='DATA ENTRY'!B80 -> 0 | C68: ='DATA ENTRY'!C80 -> 0 | I68: =IFERROR(AVERAGE(D68:H68),"0") -> 0 | O68: =IFERROR(AVERAGE(J68:N68),"0") -> 0 | Q68: =SUM(I68,O68,P68)/3 -> 0 | R68: =IFERROR(VLOOKUP(Q68,TGQC!$X$1:$Y$990,2),"0") -> 0 | S68: =VLOOKUP(R68&"-"&T68,TGQC!$N$1:$Q$56,4,0) -> Failed
... A113: 100 | B113: ='DATA ENTRY'!B125 -> 0 | C113: ='DATA ENTRY'!C125 -> 0 | I113: =IFERROR(AVERAGE(D113:H113),"0") -> 0 | O113: =IFERROR(AVERAGE(J113:N113),"0") -> 0 | Q113: =SUM(I113,O113,P113)/3 -> 0 | R113: =IFERROR(VLOOKUP(Q113,TGQC!$X$1:$Y$990,2),"0") -> 0 | S113: =VLOOKUP(R113&"-"&T113,TGQC!$N$1:$Q$56,4,0) -> Failed

Sheet GRADE SHEET
A1: WORLD CITI COLLEGES
A2: ='DATA ENTRY'!E6 -> Antipolo City
A3: GRADING SHEET
B4: SEMESTER: | C4: ='DATA ENTRY'!C10 -> 0 | D4: ACADEMIC YEAR | H4: ='DATA ENTRY'!C9 -> 0
B6: Intsructor: | C6: ='DATA ENTRY'!E9 -> 0 | F6: Day: | G6: ='DATA ENTRY'!C18 -> 0
B7: ='DATA ENTRY'!D10 -> DEAN | C7: ='DATA ENTRY'!E10 -> 0 | F7: Time: | G7: ='DATA ENTRY'!C19 -> 0
B8: Department: | C8: ='DATA ENTRY'!C11 -> 0 | F8: Room: | G8: ='DATA ENTRY'!C20 -> 0
B9: Course Code: | C9: ='DATA ENTRY'!C12 -> 0 | F9: Unit: | G9: ='DATA ENTRY'!C21 -> 0
B10: Course Description: | C10: ='DATA ENTRY'!C13 -> 0 | F10: Yr. & Sec.: | G10: ='DATA ENTRY'!E13 -> 0
B11: Subject Type: | C11: ='DATA ENTRY'!E14 -> 0
A13: SN | B13: STUDENT ID | C13: STUDENT NAME | D13: PRELIM PERIOD | E13: MIDTERM PERIOD | F13: FINAL PERIOD | G13: FINAL GRADE | H13: EQUIVALENT | I13: REMARKS | J13: REMARKS
A14: 1 | B14: ='DATA ENTRY'!B26 -> 24-QC13447 | C14: ='DATA ENTRY'!C26 -> ACOB, TRIXIE JUNIO | D14: =PRELIM!Q14 -> 92.888889 | E14: =MIDTERM!Q14 -> 88.333333 | F14: =FINAL!Q14 -> 93 | G14: =SUM(D14:F14)/3 -> 91.407407 | H14: =VLOOKUP(G14,TGQC!$X$1:$Y$990,2) -> 1.75 | I14: =VLOOKUP(H14,TGQC!$H$1:$I$13,2) -> Passed | J14: =VLOOKUP(I14&"-"&FINAL!S14,TGQC!$S$1:$V$10,4,0) -> Passed
A15: 2 | B15: ='DATA ENTRY'!B27 -> 24-QC12756 | C15: ='DATA ENTRY'!C27 -> ACOSTA, DANNMICHAEL DULLA | D15: =PRELIM!Q15 -> 90.888889 | E15: =MIDTERM!Q15 -> 81.666667 | F15: =FINAL!Q15 -> 90 | G15: =SUM(D15:F15)/3 -> 87.518519 | H15: =VLOOKUP(G15,TGQC!$X$1:$Y$990,2) -> 2 | I15: =VLOOKUP(H15,TGQC!$H$1:$I$13,2) -> Passed | J15: =VLOOKUP(I15&"-"&FINAL!S15,TGQC!$S$1:$V$10,4,0) -> Passed
A16: 3 | B16: ='DATA ENTRY'!B28 -> 24-QC12714 | C16: ='DATA ENTRY'!C28 -> AGUILAR, KIMBERLY ASHLEY CALUMPIT | D16: =PRELIM!Q16 -> 98 | E16: =MIDTERM!Q16 -> 98 | F16: =FINAL!Q16 -> 98.333333 | G16: =SUM(D16:F16)/3 -> 98.111111 | H16: =VLOOKUP(G16,TGQC!$X$1:$Y$990,2) -> 1 | I16: =VLOOKUP(H16,TGQC!$H$1:$I$13,2) -> Passed | J16: =VLOOKUP(I16&"-"&FINAL!S16,TGQC!$S$1:$V$10,4,0) -> Passed
A17: 4 | B17: ='DATA ENTRY'!B29 -> 24-QC13807 | C17: ='DATA ENTRY'!C29 -> ARANDIA, JOHN PAUL TAGULAO | D17: =PRELIM!Q17 -> 92.333333 | E17: =MIDTERM!Q17 -> 90 | F17: =FINAL!Q17 -> 95 | G17: =SUM(D17:F17)/3 -> 92.444444 | H17: =VLOOKUP(G17,TGQC!$X$1:$Y$990,2) -> 1.5 | I17: =VLOOKUP(H17,TGQC!$H$1:$I$13,2) -> Passed | J17: =VLOOKUP(I17&"-"&FINAL!S17,TGQC!$S$1:$V$10,4,0) -> Passed
A18: 5 | B18: ='DATA ENTRY'!B30 -> 24-QC13547 | C18: ='DATA ENTRY'!C30 -> AROCHA, NESHANEL | D18: =PRELIM!Q18 -> 78.888889 | E18: =MIDTERM!Q18 -> 80 | F18: =FINAL!Q18 -> 85 | G18: =SUM(D18:F18)/3 -> 81.296296 | H18: =VLOOKUP(G18,TGQC!$X$1:$Y$990,2) -> 2.5 | I18: =VLOOKUP(H18,TGQC!$H$1:$I$13,2) -> Passed | J18: =VLOOKUP(I18&"-"&FINAL!S18,TGQC!$S$1:$V$10,4,0) -> Passed
A19: 6 | B19: ='DATA ENTRY'!B31 -> 24-QC13905 | C19: ='DATA ENTRY'!C31 -> ARRIOLA, GABRIEL PEHID | D19: =PRELIM!Q19 -> 84.111111 | E19: =MIDTERM!Q19 -> 96.666667 | F19: =FINAL!Q19 -> 89.666667 | G19: =SUM(D19:F19)/3 -> 90.148148 | H19: =VLOOKUP(G19,TGQC!$X$1:$Y$990,2) -> 1.75 | I19: =VLOOKUP(H19,TGQC!$H$1:$I$13,2) -> Passed | J19: =VLOOKUP(I19&"-"&FINAL!S19,TGQC!$S$1:$V$10,4,0) -> Passed
A20: 7 | B20: ='DATA ENTRY'!B32 -> 23-QC03433 | C20: ='DATA ENTRY'!C32 -> AVILES, ANTONIO TITOY | D20: =PRELIM!Q20 -> 88.555556 | E20: =MIDTERM!Q20 -> 95 | F20: =FINAL!Q20 -> 88 | G20: =SUM(D20:F20)/3 -> 90.518519 | H20: =VLOOKUP(G20,TGQC!$X$1:$Y$990,2) -> 1.75 | I20: =VLOOKUP(H20,TGQC!$H$1:$I$13,2) -> Passed | J20: =VLOOKUP(I20&"-"&FINAL!S20,TGQC!$S$1:$V$10,4,0) -> Passed
A21: 8 | B21: ='DATA ENTRY'!B33 -> 24-QC12867 | C21: ='DATA ENTRY'!C33 -> BASILIO, CHARLES PLURAL | D21: =PRELIM!Q21 -> 97.333333 | E21: =MIDTERM!Q21 -> 98 | F21: =FINAL!Q21 -> 97.666667 | G21: =SUM(D21:F21)/3 -> 97.666667 | H21: =VLOOKUP(G21,TGQC!$X$1:$Y$990,2) -> 1 | I21: =VLOOKUP(H21,TGQC!$H$1:$I$13,2) -> Passed | J21: =VLOOKUP(I21&"-"&FINAL!S21,TGQC!$S$1:$V$10,4,0) -> Passed
A22: 9 | B22: ='DATA ENTRY'!B34 -> 24-QC14612 | C22: ='DATA ENTRY'!C34 -> BRINGINO, RALPH REGOR | D22: =PRELIM!Q22 -> 85.555556 | E22: =MIDTERM!Q22 -> 93.333333 | F22: =FINAL!Q22 -> 88 | G22: =SUM(D22:F22)/3 -> 88.962963 | H22: =VLOOKUP(G22,TGQC!$X$1:$Y$990,2) -> 1.75 | I22: =VLOOKUP(H22,TGQC!$H$1:$I$13,2) -> Passed | J22: =VLOOKUP(I22&"-"&FINAL!S22,TGQC!$S$1:$V$10,4,0) -> Passed
A23: 10 | B23: ='DATA ENTRY'!B35 -> 24-QC13948 | C23: ='DATA ENTRY'!C35 -> CABRERA, CHARLES IAN | D23: =PRELIM!Q23 -> 93.777778 | E23: =MIDTERM!Q23 -> 96.666667 | F23: =FINAL!Q23 -> 91.666667 | G23: =SUM(D23:F23)/3 -> 94.037037 | H23: =VLOOKUP(G23,TGQC!$X$1:$Y$990,2) -> 1.5 | I23: =VLOOKUP(H23,TGQC!$H$1:$I$13,2) -> Passed | J23: =VLOOKUP(I23&"-"&FINAL!S23,TGQC!$S$1:$V$10,4,0) -> Passed
A24: 11 | B24: ='DATA ENTRY'!B36 -> 24-QC13477 | C24: ='DATA ENTRY'!C36 -> CAMPOS, RYAN MIGUEL PACAYRA | D24: =PRELIM!Q24 -> 90 | E24: =MIDTERM!Q24 -> 60 | F24: =FINAL!Q24 -> 69 | G24: =SUM(D24:F24)/3 -> 73 | H24: =VLOOKUP(G24,TGQC!$X$1:$Y$990,2) -> 5 | I24: =VLOOKUP(H24,TGQC!$H$1:$I$13,2) -> Failed | J24: =VLOOKUP(I24&"-"&FINAL!S24,TGQC!$S$1:$V$10,4,0) -> Failed
A25: 12 | B25: ='DATA ENTRY'!B37 -> 24-QC14613 | C25: ='DATA ENTRY'!C37 -> CASTILLO, LOUIS ANGELO CRAME | D25: =PRELIM!Q25 -> 95.333333 | E25: =MIDTERM!Q25 -> 91.333333 | F25: =FINAL!Q25 -> 91.666667 | G25: =SUM(D25:F25)/3 -> 92.777778 | H25: =VLOOKUP(G25,TGQC!$X$1:$Y$990,2) -> 1.5 | I25: =VLOOKUP(H25,TGQC!$H$1:$I$13,2) -> Passed | J25: =VLOOKUP(I25&"-"&FINAL!S25,TGQC!$S$1:$V$10,4,0) -> Passed
... A113: 100 | B113: ='DATA ENTRY'!B125 -> 0 | C113: ='DATA ENTRY'!C125 -> 0 | D113: =PRELIM!Q113 -> 0 | E113: =MIDTERM!Q113 -> 0 | F113: =FINAL!Q113 -> 0 | G113: =SUM(D113:F113)/3 -> 0 | H113: =VLOOKUP(G113,TGQC!$X$1:$Y$990,2) -> #N/A | I113: =VLOOKUP(H113,TGQC!$H$1:$I$13,2) -> #N/A | J113: =VLOOKUP(I113&"-"&FINAL!S113,TGQC!$S$1:$V$10,4,0) -> #N/A

Sheet TGQC
A1: 1 | B1: 5 | C1: Failed | E1: INC | F1: Incomplete | H1: 1 | I1: Passed | K1: INC | L1: Incomplete | N1: =O1&"-"&P1 -> 1- | O1: 1 | Q1: Passed | S1: =T1&"-"&U1 -> Passed-Failed | T1: Passed | U1: Failed | V1: Passed | X1: 1.1 | Y1: 5
A2: 2 | B2: 5 | C2: Failed | E2: DRP | F2: Dropped | H2: 1.25 | I2: Passed | K2: DRP | L2: Dropped | N2: =O2&"-"&P2 -> 1.25- | O2: 1.25 | Q2: Passed | S2: =T2&"-"&U2 -> Failed-Failed | T2: Failed | U2: Failed | V2: Failed | X2: 1.2 | Y2: 5
A3: 3 | B3: 5 | C3: Failed | E3: IP | F3: In Progress | H3: 1.5 | I3: Passed | K3: IP | L3: In Progress | N3: =O3&"-"&P3 -> 1.5- | O3: 1.5 | Q3: Passed | S3: =T3&"-"&U3 -> Passed-Passed | T3: Passed | U3: Passed | V3: Passed | X3: 1.3 | Y3: 5
A4: 4 | B4: 5 | C4: Failed | H4: 1.75 | I4: Passed | N4: =O4&"-"&P4 -> 1.75- | O4: 1.75 | Q4: Passed | S4: =T4&"-"&U4 -> Failed-Passed | T4: Failed | U4: Passed | V4: Failed | X4: 1.4 | Y4: 5
A5: 5 | B5: 5 | C5: Failed | H5: 2 | I5: Passed | N5: =O5&"-"&P5 -> 2- | O5: 2 | Q5: Passed | S5: =T5&"-"&U5 -> Passed-Incomplete | T5: Passed | U5: Incomplete | V5: Incomplete | X5: 1.5 | Y5: 5
A6: 6 | B6: 5 | C6: Failed | H6: 2.25 | I6: Passed | N6: =O6&"-"&P6 -> 2.25- | O6: 2.25 | Q6: Passed | S6: =T6&"-"&U6 -> Passed-In Progress | T6: Passed | U6: In Progress | V6: In Progress | X6: 1.6 | Y6: 5
A7: 7 | B7: 5 | C7: Failed | H7: 2.5 | I7: Passed | N7: =O7&"-"&P7 -> 2.5- | O7: 2.5 | Q7: Passed | S7: =T7&"-"&U7 -> Passed-Dropped | T7: Passed | U7: Dropped | V7: Dropped | X7: 1.7 | Y7: 5
A8: 8 | B8: 5 | C8: Failed | H8: 2.75 | I8: Passed | N8: =O8&"-"&P8 -> 2.75- | O8: 2.75 | Q8: Passed | S8: =T8&"-"&U8 -> Failed-Incomplete | T8: Failed | U8: Incomplete | V8: Incomplete | X8: 1.8 | Y8: 5
A9: 9 | B9: 5 | C9: Failed | H9: 3 | I9: Passed | N9: =O9&"-"&P9 -> 3- | O9: 3 | Q9: Passed | S9: =T9&"-"&U9 -> Failed-In Progress | T9: Failed | U9: In Progress | V9: In Progress | X9: 1.9 | Y9: 5
A10: 10 | B10: 5 | C10: Failed | H10: 3.25 | I10: Passed | N10: =O10&"-"&P10 -> 3.25- | O10: 3.25 | Q10: Passed | S10: =T10&"-"&U10 -> Failed-Dropped | T10: Failed | U10: Dropped | V10: Dropped | X10: 2 | Y10: 5
A11: 11 | B11: 5 | C11: Failed | H11: 3.5 | I11: Passed | N11: =O11&"-"&P11 -> 3.5- | O11: 3.5 | Q11: Passed | X11: 2.1 | Y11: 5
A12: 12 | B12: 5 | C12: Failed | H12: 3.75 | I12: Passed | N12: =O12&"-"&P12 -> 3.75- | O12: 3.75 | Q12: Passed | X12: 2.2 | Y12: 5
A13: 13 | B13: 5 | C13: Failed | H13: 5 | I13: Failed | N13: =O13&"-"&P13 -> 5- | O13: 5 | Q13: Failed | X13: 2.3 | Y13: 5
A14: 14 | B14: 5 | C14: Failed | N14: =O14&"-"&P14 -> 1-INC | O14: 1 | P14: INC | Q14: Incomplete | X14: 2.4 | Y14: 5
A15: 15 | B15: 5 | C15: Failed | N15: =O15&"-"&P15 -> 1.25-INC | O15: 1.25 | P15: INC | Q15: Incomplete | X15: 2.5 | Y15: 5
A16: 16 | B16: 5 | C16: Failed | N16: =O16&"-"&P16 -> 1.5-INC | O16: 1.5 | P16: INC | Q16: Incomplete | X16: 2.6 | Y16: 5
A17: 17 | B17: 5 | C17: Failed | N17: =O17&"-"&P17 -> 1.75-INC | O17: 1.75 | P17: INC | Q17: Incomplete | X17: 2.7 | Y17: 5
A18: 18 | B18: 5 | C18: Failed | N18: =O18&"-"&P18 -> 2-INC | O18: 2 | P18: INC | Q18: Incomplete | X18: 2.8 | Y18: 5
A19: 19 | B19: 5 | C19: Failed | N19: =O19&"-"&P19 -> 2.25-INC | O19: 2.25 | P19: INC | Q19: Incomplete | X19: 2.9 | Y19: 5
A20: 20 | B20: 5 | C20: Failed | N20: =O20&"-"&P20 -> 2.5-INC | O20: 2.5 | P20: INC | Q20: Incomplete | X20: 3 | Y20: 5
A21: 21 | B21: 5 | C21: Failed | N21: =O21&"-"&P21 -> 2.75-INC | O21: 2.75 | P21: INC | Q21: Incomplete | X21: 3.1 | Y21: 5
A22: 22 | B22: 5 | C22: Failed | N22: =O22&"-"&P22 -> 3-INC | O22: 3 | P22: INC | Q22: Incomplete | X22: 3.2 | Y22: 5
A23: 23 | B23: 5 | C23: Failed | N23: =O23&"-"&P23 -> 3.25-INC | O23: 3.25 | P23: INC | Q23: Incomplete | X23: 3.3 | Y23: 5
A24: 24 | B24: 5 | C24: Failed | N24: =O24&"-"&P24 -> 3.5-INC | O24: 3.5 | P24: INC | Q24: Incomplete | X24: 3.4 | Y24: 5
A25: 25 | B25: 5 | C25: Failed | N25: =O25&"-"&P25 -> 3.75-INC | O25: 3.75 | P25: INC | Q25: Incomplete | X25: 3.5 | Y25: 5
... A55: 55 | B55: 5 | C55: Failed | N55: =O55&"-"&P55 -> 0-DRP | O55: 0 | P55: DRP | Q55: Dropped | X55: 6.5 | Y55: 5
A56: 56 | B56: 5 | C56: Failed | N56: =O56&"-"&P56 -> 0- | O56: 0 | Q56: Failed | X56: 6.6 | Y56: 5
A57: 57 | B57: 5 | C57: Failed | X57: 6.7 | Y57: 5
A58: 58 | B58: 5 | C58: Failed | X58: 6.8 | Y58: 5
A59: 59 | B59: 5 | C59: Failed | X59: 6.9 | Y59: 5
A60: 60 | B60: 5 | C60: Failed | X60: 7 | Y60: 5
A61: 61 | B61: 5 | C61: Failed | X61: 7.1 | Y61: 5
A62: 62 | B62: 5 | C62: Failed | X62: 7.2 | Y62: 5
A63: 63 | B63: 5 | C63: Failed | X63: 7.3 | Y63: 5
A64: 64 | B64: 5 | C64: Failed | X64: 7.4 | Y64: 5
A65: 65 | B65: 5 | C65: Failed | X65: 7.5 | Y65: 5
A66: 66 | B66: 5 | C66: Failed | X66: 7.6 | Y66: 5
A67: 67 | B67: 5 | C67: Failed | X67: 7.7 | Y67: 5
A68: 68 | B68: 5 | C68: Failed | X68: 7.8 | Y68: 5
... A100: 100 | B100: 1 | C100: Passed | X100: 11 | Y100: 5
...

Sheet Data
A1: College of Accountancy | B1: DEAN
A2: College of Arts and Sciences | B2: PROGRAM HEAD
A3: College of Business Administration
A4: College of Communication and Arts | B4: ACADEMIC HEAD
A5: College of Criminology | B5: CAMPUS MANAGER
A6: College of Information Technology | B6: AVP FOR ACADEMIC AFFAIRS
A7: College of Medical Technology
A8: College of Nursing
A9: College of Pharmacy
A10: College of Physical Therapy
A11: College of Psychology
A12: College of Radiologic Technology
A13: Graduate School
A14: School of International Hospitality Management
A17: Bachelor of Arts in Communication
A18: Bachelor of Science in Accountanty
A19: Bachelor of Science in Business Administration
A20: Bachelor of Science in Criminology
... A40: PERFORMANCE TASK (PT)
